<?xml version="1.0"?><robot name="flexible">
  <link name="base_link">
    <visual>
      <origin rpy="0 0.0 0" xyz="0 0 -0.028"/>
      <geometry>
        <box size="0.1 0.1 0.056"/>
      </geometry>
      <material name="blue">
        <color rgba="0 0 0.8 1.0"/>
      </material>
    </visual>
  </link>

  <link name="lf_leg1">
    <visual>
      <origin xyz="0.015 0.0 0.0"/>
      <geometry>
        <box size="0.03 0.005 0.005"/>
      </geometry>
      <material name="white">
        <color rgba="1 1 1 1"/>
      </material>
    </visual>
  </link>

  <link name="lf_leg2">
    <visual>
      <origin xyz="0.035 0.0 0.0"/>
      <geometry>
        <box size="0.07 0.005 0.005"/>
      </geometry>
      <material name="white">
        <color rgba="1 1 1 1"/>
      </material>
    </visual>
  </link>

  <joint name="base_to_lf_leg1" type="revolute">
    <parent link="base_link"/>
    <child link="lf_leg1"/>
    <origin xyz="0.032 0.055 -0.012"/>
    <axis xyz="0 1 0" />
  </joint>

  <joint name="lf_joint" type="revolute">
    <parent link="lf_leg1"/>
    <child link="lf_leg2"/>
    <origin xyz="0.03 0.0 0.0"/>
    <axis xyz="0 1 0" />
  </joint>

  <link name="lr_leg1">
    <visual>
      <origin xyz="-0.015 0.0 0.0"/>
      <geometry>
        <box size="0.03 0.005 0.005"/>
      </geometry>
      <material name="white">
        <color rgba="1 1 1 1"/>
      </material>
    </visual>
  </link>

  <link name="lr_leg2">
    <visual>
      <origin xyz="-0.035 0.0 0.0"/>
      <geometry>
        <box size="0.07 0.005 0.005"/>
      </geometry>
      <material name="white">
        <color rgba="1 1 1 1"/>
      </material>
    </visual>
  </link>

  <joint name="base_to_lr_leg1" type="revolute">
    <parent link="base_link"/>
    <child link="lr_leg1"/>
    <origin xyz="-0.032 0.055 -0.012"/>
    <axis xyz="0 1 0" />
  </joint>

  <joint name="lr_joint" type="revolute">
    <parent link="lr_leg1"/>
    <child link="lr_leg2"/>
    <origin xyz="-0.03 0.0 0.0"/>
    <axis xyz="0 1 0" />
  </joint>

  <link name="rf_leg1">
    <visual>
      <origin xyz="0.015 0.0 0.0"/>
      <geometry>
        <box size="0.03 0.005 0.005"/>
      </geometry>
      <material name="white">
        <color rgba="1 1 1 1"/>
      </material>
    </visual>
  </link>

  <link name="rf_leg2">
    <visual>
      <origin xyz="0.035 0.0 0.0"/>
      <geometry>
        <box size="0.07 0.005 0.005"/>
      </geometry>
      <material name="white">
        <color rgba="1 1 1 1"/>
      </material>
    </visual>
  </link>

  <joint name="base_to_rf_leg1" type="revolute">
    <parent link="base_link"/>
    <child link="rf_leg1"/>
    <origin xyz="0.032 -0.055 -0.012"/>
    <axis xyz="0 1 0" />
  </joint>

  <joint name="rf_joint" type="revolute">
    <parent link="rf_leg1"/>
    <child link="rf_leg2"/>
    <origin xyz="0.03 0.0 0.0"/>
    <axis xyz="0 1 0" />
  </joint>

  <link name="rr_leg1">
    <visual>
      <origin xyz="-0.015 0.0 0.0"/>
      <geometry>
        <box size="0.03 0.005 0.005"/>
      </geometry>
      <material name="white">
        <color rgba="1 1 1 1"/>
      </material>
    </visual>
  </link>

  <link name="rr_leg2">
    <visual>
      <origin xyz="-0.035 0.0 0.0"/>
      <geometry>
        <box size="0.07 0.005 0.005"/>
      </geometry>
      <material name="white">
        <color rgba="1 1 1 1"/>
      </material>
    </visual>
  </link>

  <joint name="base_to_rr_leg1" type="revolute">
    <parent link="base_link"/>
    <child link="rr_leg1"/>
    <origin xyz="-0.032 -0.055 -0.012"/>
    <axis xyz="0 1 0" />
  </joint>

  <joint name="rr_joint" type="revolute">
    <parent link="rr_leg1"/>
    <child link="rr_leg2"/>
    <origin xyz="-0.03 0.0 0.0"/>
    <axis xyz="0 1 0" />
  </joint>

</robot>